Workbook

Sheet sozluk
A1: ability | B1: Ebılıti | C1: hüner [i.] | D1: kabiliyet [i.] | E1: yetenek [i.] | F1: A1 | K1: 531
A2: able | B2: Eybıl | C2: hünerli [s.] | D2: kadir [s.] | E2: gücü yeten [s.] | F2: A1
A3: abroad | B3: Ebrod | C3: yurt dışında [zf.] | D3: gurbet [i.] | E3: yurt dışı [i.] | F3: A1
A4: accept | B4: Eksept | C4: kabullenmek [f.] | D4: kabul etmek [f.] | E4: almak [f.] | F4: A1
A5: accident | B5: Eksidınt | C5: rastlantı [i.] | D5: kaza [i.] | E5: beklenmedik olay [i.] | F5: A1
A6: according to | B6: Ekording Tu | C6: göre [ed.] | D6: uyarınca [ed.] | E6: üzere [ed.] | F6: A1
A7: achieve | B7: Açiv | C7: elde etmek [f.] | D7: başarmak [f.] | E7: ulaşmak [f.] | F7: A1
A8: act | B8: Ekt | C8: davranmak [f.] | D8: hareket etmek [f.] | E8: eylem [i.] | F8: A1
A9: active | B9: Ektiv | C9: faal [s.] | D9: aktif [s.] | E9: etkin [s.] | F9: A1
A10: actually | B10: Ekçueli | C10: fiilen [zf.] | D10: aslında [zf.] | E10: hem [zf.] | F10: A1
A11: adult | B11: Edalt | C11: yetişkin [i.] | D11: er kişi [i.] | E11: yetişkin kişi [i.] | F11: A1
A12: advantage | B12: Edventıc | C12: avantaj [i.] | D12: fayda [i.] | E12: yarar [i.] | F12: A1
A13: adventure | B13: Edvençur | C13: macera [i.] | D13: serüven [i.] | E13: atılmak [f.] | F13: A1
... A41: anywhere | B41: Eniveır | C41: nerede olursa olsun [zf.] | D41: herhangi bir yer [zf.] | E41: herhangi bir yerde [zf.] | F41: A1
A42: app | B42: Ep | C42: uygulama | F42: A1
A43: appear | B43: Eppiır | C43: belli olmak [f.] | D43: görünmek [f.] | E43: belirmek [f.] | F43: A1
A44: appearance | B44: Eppiırıns | C44: dış görünüş [i.] | D44: görünüm [i.] | E44: görünüş [i.] | F44: A1
A45: apply | B45: Eplay | C45: uygulamak [f.] | D45: başvurmak [f.] | E45: müracaat etmek [f.] | F45: A1
A46: architect | B46: Arkitekt | C46: mimar [i.] | D46: yapmak [f.] | E46: tasarlamak [f.] | F46: A1
A47: architecture | B47: Arkitekçır | C47: mimarlık [i.] | D47: inşaat [i.] | E47: yapı [i.] | F47: A1
A48: argue | B48: Argüu | C48: tartışmak [f.] | D48: çekişmek [f.] | E48: göstergesi olmak [f.] | F48: A1
A49: argument | B49: Argümınt | C49: argüman [i.] | D49: tartışma [i.] | E49: sav [i.] | F49: A1
A50: army | B50: Armi | C50: ordu [i.] | D50: kalabalık [i.] | E50: topluluk [i.] | F50: A1
A51: arrange | B51: Ereync | C51: ayarlamak [f.] | D51: düzenlemek [f.] | E51: hazırlanmak [f.] | F51: A1
A52: arrangement | B52: Ereyncmınt | C52: ayarlama [i.] | D52: aranjman [i.] | E52: düzenleme [i.] | F52: A1
A53: as | B53: Ez | C53: olarak [zf.] | D53: gibi [ed.] | E53: dahi [zf.] | F53: A1
A54: asleep | B54: Esliip | C54: uyuyan [s.] | D54: tembel [s.] | E54: uyuşuk [s.] | F54: A1
... A87: between | B87: bitvin | C87: arasında [zf.] | D87: arasına [zf.] | E87: ortada [zf.] | F87: A1
A88: billion | B88: Bilyın | C88: milyar [i.] | D88: bilyon [i.] | F88: A1
A89: bin | B89: Bin | C89: çöp kutusu [i.] | D89: ambarlamak [f.] | E89: çöpe atmak [f.] | F89: A1
A90: biology | B90: Bayoloci | C90: dirimbilim [i.] | D90: yaşambilim [i.] | E90: biyoloji [i.] | F90: A1
A91: birth | B91: Börth | C91: doğum [i.] | D91: kaynak [i.] | E91: doğum [i.] | F91: A1
A92: biscuit | B92: Biskit | C92: bisküvi [i.] | D92: gevrek [i.] | E92: bisküvi [i.] | F92: A1
A93: bit | B93: Bit | C93: gem [i.] | D93: gemlemek [f.] | E93: ikili savmak [f.] | F93: A1
A94: blank | B94: Blenk | C94: boşluk [i.] | D94: boş [s.] | E94: silmek [f.] | F94: A1
A95: blood | B95: Blad | C95: kan [i.] | D95: kan bağı [i.] | E95: dem [i.] | F95: A1
A96: blow | B96: Blou | C96: esmek [f.] | D96: üflemek [f.] | E96: darbe [i.] | F96: A1
A97: board | B97: Boord | C97: binmek [f.] | D97: tahta döşemek [f.] | E97: kurul [i.] | F97: A1
A98: boil | B98: Boıl | C98: haşlamak [f.] | D98: kaynamak [f.] | E98: çıban [i.] | F98: A1
A99: bone | B99: Boun | C99: kılçık [i.] | D99: kemik [i.] | E99: kılçıklarını ayıklamak (balık) [f.] | F99: A1
...

Sheet tum kelimeler
A1: Kelime | B1: Frekans | C1: türkçe_okunuş | F1: anlam1 | G1: anlam2 | H1: anlam3 | I1: seviye
A2: about | B2: 469 | C2: Ebaut | D2: =IF(C2<>"",C2,VLOOKUP(A2,Sayfa2!$A$1:$C$9998,2,FALSE)) -> Ebaut | E2: =IF(C2<>"",F2,VLOOKUP(A2,Sayfa2!$A$1:$C$9998,3,FALSE)) -> hemen hemen [zf.] | F2: hemen hemen [zf.] | G2: aşağı yukarı [zf.] | H2: yaklaşık [zf.] | I2: A2
A3: up | B3: 456 | C3: Ap | D3: =IF(C3<>"",C3,VLOOKUP(A3,Sayfa2!$A$1:$C$9998,2,FALSE)) -> Ap | E3: =IF(C3<>"",F3,VLOOKUP(A3,Sayfa2!$A$1:$C$9998,3,FALSE)) -> yukarı [ünl.] | F3: yukarı [ünl.] | G3: yükseltmek [f.] | H3: artırmak [f.] | I3: A2
A4: but | B4: 454 | C4: Bat | D4: =IF(C4<>"",C4,VLOOKUP(A4,Sayfa2!$A$1:$C$9998,2,FALSE)) -> Bat | E4: =IF(C4<>"",F4,VLOOKUP(A4,Sayfa2!$A$1:$C$9998,3,FALSE)) -> ancak [bağ.] | F4: ancak [bağ.] | G4: fakat [bağ.] | H4: itiraz [i.] | I4: A2
A5: get | B5: 428 | C5: Get | D5: =IF(C5<>"",C5,VLOOKUP(A5,Sayfa2!$A$1:$C$9998,2,FALSE)) -> Get | E5: =IF(C5<>"",F5,VLOOKUP(A5,Sayfa2!$A$1:$C$9998,3,FALSE)) -> elde etmek [f.] | F5: elde etmek [f.] | G5: almak [f.] | H5: kazanmak [f.] | I5: A2
A6: her | B6: 420 | C6: Hör | D6: =IF(C6<>"",C6,VLOOKUP(A6,Sayfa2!$A$1:$C$9998,2,FALSE)) -> Hör | E6: =IF(C6<>"",F6,VLOOKUP(A6,Sayfa2!$A$1:$C$9998,3,FALSE)) -> ona [zm.] | F6: ona [zm.] | G6: dişil onu [zm.] | H6: ondan [zm.] | I6: A2
A7: like | B7: 416 | C7: layk | D7: =IF(C7<>"",C7,VLOOKUP(A7,Sayfa2!$A$1:$C$9998,2,FALSE)) -> layk | E7: =IF(C7<>"",F7,VLOOKUP(A7,Sayfa2!$A$1:$C$9998,3,FALSE)) -> beğenmek [f.] | F7: beğenmek [f.] | G7: hoşlanmak [f.] | H7: sevmek [f.] | I7: A2
A8: from | B8: 387 | C8: from | D8: =IF(C8<>"",C8,VLOOKUP(A8,Sayfa2!$A$1:$C$9998,2,FALSE)) -> from | E8: =IF(C8<>"",F8,VLOOKUP(A8,Sayfa2!$A$1:$C$9998,3,FALSE)) -> itibaren [ed.] | F8: itibaren [ed.] | G8: -den beri [ed.] | H8: -den [ed.] | I8: A2
A9: time | B9: 385 | C9: Taym | D9: =IF(C9<>"",C9,VLOOKUP(A9,Sayfa2!$A$1:$C$9998,2,FALSE)) -> Taym | E9: =IF(C9<>"",F9,VLOOKUP(A9,Sayfa2!$A$1:$C$9998,3,FALSE)) -> kez [i.] | F9: kez [i.] | G9: kere [i.] | H9: müddet [i.] | I9: A2
A10: had | B10: 383 | C10: Hed | D10: =IF(C10<>"",C10,VLOOKUP(A10,Sayfa2!$A$1:$C$9998,2,FALSE)) -> Hed | E10: =IF(C10<>"",F10,VLOOKUP(A10,Sayfa2!$A$1:$C$9998,3,FALSE)) -> 0 | F10: 0
A11: when | B11: 383 | C11: Wen | D11: =IF(C11<>"",C11,VLOOKUP(A11,Sayfa2!$A$1:$C$9998,2,FALSE)) -> Wen | E11: =IF(C11<>"",F11,VLOOKUP(A11,Sayfa2!$A$1:$C$9998,3,FALSE)) -> ne zaman [zf.] | F11: ne zaman [zf.] | G11: zaman [i.] | H11: ne vakit [zf.] | I11: A2
A12: how | B12: 379 | C12: Haw | D12: =IF(C12<>"",C12,VLOOKUP(A12,Sayfa2!$A$1:$C$9998,2,FALSE)) -> Haw | E12: =IF(C12<>"",F12,VLOOKUP(A12,Sayfa2!$A$1:$C$9998,3,FALSE)) -> nasıl [zf.] | F12: nasıl [zf.] | G12: yapma yöntemi [i.] | H12: yapma tarzı [i.] | I12: A2
A13: there | B13: 371 | C13: Theer | D13: =IF(C13<>"",C13,VLOOKUP(A13,Sayfa2!$A$1:$C$9998,2,FALSE)) -> Theer | E13: =IF(C13<>"",F13,VLOOKUP(A13,Sayfa2!$A$1:$C$9998,3,FALSE)) -> oraya [zf.] | F13: oraya [zf.] | G13: orada [zf.] | H13: ora [zf.] | I13: A2
A14: out | B14: 359 | C14: Aut | D14: =IF(C14<>"",C14,VLOOKUP(A14,Sayfa2!$A$1:$C$9998,2,FALSE)) -> Aut | E14: =IF(C14<>"",F14,VLOOKUP(A14,Sayfa2!$A$1:$C$9998,3,FALSE)) -> çıkış [i.] | F14: çıkış [i.] | G14: dışarıda [zf.] | H14: dışarı [zf.] | I14: A2
A15: by | B15: 354 | C15: bay | D15: =IF(C15<>"",C15,VLOOKUP(A15,Sayfa2!$A$1:$C$9998,2,FALSE)) -> bay | E15: =IF(C15<>"",F15,VLOOKUP(A15,Sayfa2!$A$1:$C$9998,3,FALSE)) -> geçecek biçimde [zf.] | F15: geçecek biçimde [zf.] | G15: yakın [zf.] | H15: evde [zf.] | I15: A2
A16: people | B16: 354 | C16: Piipl | D16: =IF(C16<>"",C16,VLOOKUP(A16,Sayfa2!$A$1:$C$9998,2,FALSE)) -> Piipl | E16: =IF(C16<>"",F16,VLOOKUP(A16,Sayfa2!$A$1:$C$9998,3,FALSE)) -> insanlar [i.] | F16: insanlar [i.] | G16: ulus [i.] | H16: halk [i.] | I16: A2
A17: would | B17: 348 | C17: Vud | D17: =IF(C17<>"",C17,VLOOKUP(A17,Sayfa2!$A$1:$C$9998,2,FALSE)) -> Vud | E17: =IF(C17<>"",F17,VLOOKUP(A17,Sayfa2!$A$1:$C$9998,3,FALSE)) -> istemek [f.] | F17: istemek [f.] | G17: -ecekti [f.] | H17: -çekti [f.] | I17: A2
A18: more | B18: 339 | C18: Mor | D18: =IF(C18<>"",C18,VLOOKUP(A18,Sayfa2!$A$1:$C$9998,2,FALSE)) -> Mor | E18: =IF(C18<>"",F18,VLOOKUP(A18,Sayfa2!$A$1:$C$9998,3,FALSE)) -> daha fazla [s.] | F18: daha fazla [s.] | G18: daha [zf.] | H18: fazla şey [i.] | I18: A2
A19: all | B19: 335 | C19: Ol | D19: =IF(C19<>"",C19,VLOOKUP(A19,Sayfa2!$A$1:$C$9998,2,FALSE)) -> Ol | E19: =IF(C19<>"",F19,VLOOKUP(A19,Sayfa2!$A$1:$C$9998,3,FALSE)) -> tüm [i.] | F19: tüm [i.] | G19: bütün [i.] | H19: hepsi [zm.] | I19: A1
A20: go | B20: 314 | C20: Go | D20: =IF(C20<>"",C20,VLOOKUP(A20,Sayfa2!$A$1:$C$9998,2,FALSE)) -> Go | E20: =IF(C20<>"",F20,VLOOKUP(A20,Sayfa2!$A$1:$C$9998,3,FALSE)) -> hareket etmek [f.] | F20: hareket etmek [f.] | G20: gitmek [f.] | H20: went - gone [f.] | I20: A2
A21: their | B21: 298 | C21: Theır | D21: =IF(C21<>"",C21,VLOOKUP(A21,Sayfa2!$A$1:$C$9998,2,FALSE)) -> Theır | E21: =IF(C21<>"",F21,VLOOKUP(A21,Sayfa2!$A$1:$C$9998,3,FALSE)) -> onların [zm.] | F21: onların [zm.] | G21: 0 | H21: 0 | I21: A2
A22: our | B22: 296 | C22: Aar | D22: =IF(C22<>"",C22,VLOOKUP(A22,Sayfa2!$A$1:$C$9998,2,FALSE)) -> Aar | E22: =IF(C22<>"",F22,VLOOKUP(A22,Sayfa2!$A$1:$C$9998,3,FALSE)) -> bizim [zm.] | F22: bizim [zm.] | G22: bizim [zm.] | H22: 0 | I22: A2
A23: just | B23: 282 | C23: Cast | D23: =IF(C23<>"",C23,VLOOKUP(A23,Sayfa2!$A$1:$C$9998,2,FALSE)) -> Cast | E23: =IF(C23<>"",F23,VLOOKUP(A23,Sayfa2!$A$1:$C$9998,3,FALSE)) -> sadece [s.] | F23: sadece [s.] | G23: adil [s.] | H23: yalnızca [zf.] | I23: A2
A24: his | B24: 278 | C24: Hiz | D24: =IF(C24<>"",C24,VLOOKUP(A24,Sayfa2!$A$1:$C$9998,2,FALSE)) -> Hiz | E24: =IF(C24<>"",F24,VLOOKUP(A24,Sayfa2!$A$1:$C$9998,3,FALSE)) -> eril onunki [zm.] | F24: eril onunki [zm.] | G24: onun [zm.] | H24: onunki [zm.] | I24: A1
A25: need | B25: 264 | C25: Niid | D25: =IF(C25<>"",C25,VLOOKUP(A25,Sayfa2!$A$1:$C$9998,2,FALSE)) -> Niid | E25: =IF(C25<>"",F25,VLOOKUP(A25,Sayfa2!$A$1:$C$9998,3,FALSE)) -> ihtiyaç duymak [f.] | F25: ihtiyaç duymak [f.] | G25: gerek [i.] | H25: gereksinim [i.] | I25: A1
A26: some | B26: 259 | C26: Sam | D26: =IF(C26<>"",C26,VLOOKUP(A26,Sayfa2!$A$1:$C$9998,2,FALSE)) -> Sam | E26: =IF(C26<>"",F26,VLOOKUP(A26,Sayfa2!$A$1:$C$9998,3,FALSE)) -> biraz [s.] | F26: biraz [s.] | G26: bazı [s.] | H26: birkaç [s.] | I26: A2
A27: work | B27: 246 | C27: Wörk | D27: =IF(C27<>"",C27,VLOOKUP(A27,Sayfa2!$A$1:$C$9998,2,FALSE)) -> Wörk | E27: =IF(C27<>"",F27,VLOOKUP(A27,Sayfa2!$A$1:$C$9998,3,FALSE)) -> çalışmak [f.] | F27: çalışmak [f.] | G27: işe yaramak [f.] | H27: iş yapmak [f.] | I27: A2
A28: or | B28: 231 | C28: Or | D28: =IF(C28<>"",C28,VLOOKUP(A28,Sayfa2!$A$1:$C$9998,2,FALSE)) -> Or | E28: =IF(C28<>"",F28,VLOOKUP(A28,Sayfa2!$A$1:$C$9998,3,FALSE)) -> ya da [bağ.] | F28: ya da [bağ.] | G28: veya [bağ.] | H28: altın sarısı [i.] | I28: A2
A29: should | B29: 226 | C29: Şud | D29: =IF(C29<>"",C29,VLOOKUP(A29,Sayfa2!$A$1:$C$9998,2,FALSE)) -> Şud | E29: =IF(C29<>"",F29,VLOOKUP(A29,Sayfa2!$A$1:$C$9998,3,FALSE)) -> gerekmek [f.] | F29: gerekmek [f.] | G29: -malı [f.] | H29: -meli [f.] | I29: A2
A30: know | B30: 224 | C30: Nou | D30: =IF(C30<>"",C30,VLOOKUP(A30,Sayfa2!$A$1:$C$9998,2,FALSE)) -> Nou | E30: =IF(C30<>"",F30,VLOOKUP(A30,Sayfa2!$A$1:$C$9998,3,FALSE)) -> bilmek [f.] | F30: bilmek [f.] | G30: tanımak [f.] | H30: knew - known [f.] | I30: A2
A31: see | B31: 224 | C31: Sii | D31: =IF(C31<>"",C31,VLOOKUP(A31,Sayfa2!$A$1:$C$9998,2,FALSE)) -> Sii | E31: =IF(C31<>"",F31,VLOOKUP(A31,Sayfa2!$A$1:$C$9998,3,FALSE)) -> görmek [f.] | F31: görmek [f.] | G31: bakmak [f.] | H31: saw - seen [f.] | I31: A2
A32: here | B32: 221 | C32: Hiır | D32: =IF(C32<>"",C32,VLOOKUP(A32,Sayfa2!$A$1:$C$9998,2,FALSE)) -> Hiır | E32: =IF(C32<>"",F32,VLOOKUP(A32,Sayfa2!$A$1:$C$9998,3,FALSE)) -> burada [zf.] | F32: burada [zf.] | G32: buraya [zf.] | H32: burda [zf.] | I32: A2
A33: new | B33: 220 | C33: Nuu | D33: =IF(C33<>"",C33,VLOOKUP(A33,Sayfa2!$A$1:$C$9998,2,FALSE)) -> Nuu | E33: =IF(C33<>"",F33,VLOOKUP(A33,Sayfa2!$A$1:$C$9998,3,FALSE)) -> yeni [s.] | F33: yeni [s.] | G33: keşfedilmemiş [s.] | H33: değişik [s.] | I33: A2
A34: no | B34: 220 | C34: No | D34: =IF(C34<>"",C34,VLOOKUP(A34,Sayfa2!$A$1:$C$9998,2,FALSE)) -> No | E34: =IF(C34<>"",F34,VLOOKUP(A34,Sayfa2!$A$1:$C$9998,3,FALSE)) -> hayır [ünl.] | F34: hayır [ünl.] | G34: aleyhte oy [i.] | H34: red [i.] | I34: A2
... A43: us | B43: 197 | C43: As | D43: =IF(C43<>"",C43,VLOOKUP(A43,Sayfa2!$A$1:$C$9998,2,FALSE)) -> As | E43: =IF(C43<>"",F43,VLOOKUP(A43,Sayfa2!$A$1:$C$9998,3,FALSE)) -> biz [zm.] | F43: biz [zm.] | G43: abd [i.] | H43: bizi [zm.] | I43: A2
A44: them | B44: 195 | C44: Them | D44: =IF(C44<>"",C44,VLOOKUP(A44,Sayfa2!$A$1:$C$9998,2,FALSE)) -> Them | E44: =IF(C44<>"",F44,VLOOKUP(A44,Sayfa2!$A$1:$C$9998,3,FALSE)) -> onlara [zm.] | F44: onlara [zm.] | G44: onları [zm.] | H44: 0 | I44: A2
A45: than | B45: 194 | C45: Den | D45: =IF(C45<>"",C45,VLOOKUP(A45,Sayfa2!$A$1:$C$9998,2,FALSE)) -> Den | E45: =IF(C45<>"",F45,VLOOKUP(A45,Sayfa2!$A$1:$C$9998,3,FALSE)) -> -den [ed.] | F45: -den [ed.] | G45: hariç [ed.] | H45: -mektense [ed.] | I45: A2
A46: who | B46: 193 | C46: Hu | D46: =IF(C46<>"",C46,VLOOKUP(A46,Sayfa2!$A$1:$C$9998,2,FALSE)) -> Hu | E46: =IF(C46<>"",F46,VLOOKUP(A46,Sayfa2!$A$1:$C$9998,3,FALSE)) -> kimi [zm.] | F46: kimi [zm.] | G46: kim [zm.] | H46: kime [zm.] | I46: A2
A47: really | B47: 184 | C47: Riıli | D47: =IF(C47<>"",C47,VLOOKUP(A47,Sayfa2!$A$1:$C$9998,2,FALSE)) -> Riıli | E47: =IF(C47<>"",F47,VLOOKUP(A47,Sayfa2!$A$1:$C$9998,3,FALSE)) -> hakikaten [zf.] | F47: hakikaten [zf.] | G47: gerçekten [zf.] | H47: cidden [zf.] | I47: A2
A48: good | B48: 182 | C48: Gud | D48: =IF(C48<>"",C48,VLOOKUP(A48,Sayfa2!$A$1:$C$9998,2,FALSE)) -> Gud | E48: =IF(C48<>"",F48,VLOOKUP(A48,Sayfa2!$A$1:$C$9998,3,FALSE)) -> güzel [s.] | F48: güzel [s.] | G48: hayırlı [s.] | H48: iyi [s.] | I48: A1
...

Sheet Sayfa2
A1: İngilizce | B1: Türkçe Okunuş | C1: Türkçe Anlam
A2: had | B2: Hed | C2: sahipti
A3: got | B3: Gat | C3: aldı / oldu
A4: did | B4: Did | C4: yaptı
A5: these | B5: Diz | C5: bunlar
A6: said | B6: Sed | C6: söyledi
A7: years | B7: Yirz | C7: yıllar
A8: made | B8: Meyd | C8: yaptı
A9: didn't | B9: Didınt | C9: yapmadı
A10: things | B10: Tings | C10: şeyler
A11: that's | B11: Dets | C11: o / şu
A12: ended | B12: Endid | C12: sona erdi
... A2285: letters | B2285: Letırz | C2285: harfler / mektuplar
A2286: lgbt | B2286: El ci bi ti | C2286: LGBT (lezbiyen | D2286: gey | E2286: biseksüel | F2286: trans)
A2287: libraries | B2287: Laybrəriz | C2287: kütüphaneler
A2288: lied | B2288: Layd | C2288: yalan söyledi
A2289: lifesaver | B2289: Layfseyvır | C2289: cankurtaran (hayat kurtaran)
A2290: lifestyles | B2290: Layfstayls | C2290: yaşam tarzları
A2291: liffey | B2291: Lifi | C2291: Liffey (nehir)
A2292: lifts | B2292: Lifts | C2292: kaldırır / asansörler
A2293: limits | B2293: Limits | C2293: sınırlar
A2294: linda | B2294: Lində | C2294: Linda (isim)
A2295: liquids | B2295: Likvits | C2295: sıvılar
A2296: lobster | B2296: Labstır | C2296: ıstakoz
A2297: locally | B2297: Lokəli | C2297: yerel olarak
A2298: locking | B2298: Lokin | C2298: kilitleme
... A2421: peope | B2421: Pipl | C2421: insanlar (yanlış yazım: people)
A2422: performances | B2422: P
A2423: careers | B2423: Kariyırz | C2423: kariyerler
A2424: carnivores | B2424: Karnivors | C2424: etoburlar
A2425: casuals | B2425: Kazuıls | C2425: gündelik şeyler / sıradanlar
A2426: cat's | B2426: Kets | C2426: kedinin
A2427: categorize | B2427: Ketıgorayz | C2427: kategorilere ayırmak
A2428: caterer | B2428: Keytırır | C2428: yemek servisi yapan kişi / kurum
A2429: catering | B2429: Keytiring | C2429: yemek servisi / catering
A2430: cath | B2430: Keth | C2430: Kath (isim kısaltması)
A2431: cellphone | B2431: Selfovn | C2431: cep telefonu
A2432: ceo | B2432: Si i ov | C2432: CEO (genel müdür)
A2433: ceramic | B2433: Sıremik | C2433: seramik
A2434: cfo | B2434: Si ef ov | C2434: CFO (finans müdürü)
...
